2023-03-27 18:26:39,228:app.main_bp:WARNING:Index page says 'Hello!'
2023-03-27 18:27:00,904:app.main_bp:INFO:Index page says 'Hello!'
2023-03-31 10:57:26,117:app.main_bp:INFO:Index page says 'Hello!'
2023-03-31 10:57:40,447:app.main_bp:INFO:Index page says 'Hello!'
2023-03-31 11:06:40,725:app.main_bp:INFO:Index page says 'Hello!'
2023-03-31 11:06:50,718:app.main_bp:INFO:Index page says 'Hello!'
2023-03-31 11:07:05,114:app.main_bp:INFO:Index page says 'Hello!'
2023-03-31 11:07:09,758:app.main_bp:INFO:Index page says 'Hello!'
2023-03-31 11:07:27,820:app.main_bp:INFO:Index page says 'Hello!'
2023-03-31 11:14:58,776:app.main_bp:INFO:Index page says 'Hello!'
2023-03-31 11:15:12,004:app.main_bp:INFO:Index page says 'Hello!'
2023-03-31 11:16:29,692:app.main_bp:INFO:Index page says 'Hello!'
2023-03-31 11:16:55,361:app.main_bp:INFO:Index page says 'Hello!'
2023-03-31 12:10:50,564:app.main_bp:INFO:Index page says 'Hello!'
2023-03-31 12:11:02,617:app.main_bp:INFO:Index page says 'Hello!'
2023-03-31 12:11:25,166:app.main_bp:INFO:Index page says 'Hello!'
2023-03-31 12:13:35,825:app.main_bp:INFO:Index reject_form says 'Hello!'
2023-03-31 12:14:02,868:app.main_bp:INFO:Index reject_form says 'Hello!'
2023-03-31 12:16:16,489:app.main_bp:INFO:Index reject_form.get says 'Hello!'
2023-03-31 12:16:35,723:app.main_bp:INFO:Index reject_form.get says 'Hello!'
2023-03-31 12:16:37,448:app.main_bp:INFO:Index reject_form.get says 'Hello!'
2023-03-31 12:17:14,220:app.main_bp:INFO:Index reject_form.get says 'Hello!'
2023-03-31 12:17:16,610:app.main_bp:INFO:Index reject_form.get says 'Hello!'
2023-03-31 12:17:43,843:app.main_bp:INFO:Index reject_form.get says 'Hello!'
2023-03-31 12:17:45,957:app.main_bp:INFO:Index reject_form.get says 'Hello!'
2023-03-31 12:18:08,898:app.main_bp:INFO:Index reject_form.get says 'Hello!'
2023-03-31 12:21:18,279:app.main_bp:INFO:Index reject_form.get says 'Hello!'
2023-03-31 12:21:21,120:app.main_bp:INFO:Index reject_form.post says 'Hello!'
2023-03-31 12:21:21,147:app.main_bp:INFO:Index page says 'Hello!'
2023-03-31 12:31:52,510:app.main_bp:INFO:Index page says 'Hello!'
2023-03-31 12:31:55,315:app.main_bp:INFO:Index reject_form.get says 'Hello!'
2023-03-31 12:32:02,131:app.main_bp:INFO:Index reject_form.get says 'Hello!'
2023-03-31 12:32:28,481:app.main_bp:INFO:Index reject_form.get says 'Hello!'
2023-03-31 12:32:29,625:app.main_bp:INFO:Index reject_form.get says 'Hello!'
2023-03-31 12:33:33,462:app.main_bp:INFO:Index reject_form.get says 'Hello!'
2023-03-31 12:33:50,508:app.main_bp:INFO:Index reject_form.get says 'Hello!'
2023-03-31 12:35:20,452:app.main_bp:INFO:Index reject_form.get says 'Hello!'
2023-03-31 12:35:33,594:app.main_bp:INFO:Index reject_form.post says 'Hello!'
2023-03-31 12:37:05,002:app.main_bp:INFO:Index reject_form.post says 'Hello!'
2023-03-31 12:37:05,003:app.main_bp:DEBUG:Reason: я маленькая причина


2023-03-31 12:37:05,008:app.main_bp:INFO:Index page says 'Hello!'
2023-03-31 12:37:08,097:app.main_bp:INFO:Index reject_form.get says 'Hello!'
2023-03-31 12:37:11,433:app.main_bp:INFO:Index reject_form.post says 'Hello!'
2023-03-31 12:37:11,433:app.main_bp:DEBUG:Reason: adas
2023-03-31 12:37:11,468:app.main_bp:INFO:Index page says 'Hello!'
2023-03-31 13:28:22,912:app.main_bp:INFO:Index page says 'Hello!'
2023-03-31 13:31:06,561:app.main_bp:INFO:Index page says 'Hello!'
2023-03-31 13:32:35,716:app.main_bp:INFO:Index page says 'Hello!'
2023-03-31 14:22:21,796:app.main_bp:ERROR:Add msg fails with (mariadb.OperationalError) Unknown column 'time_updated' in 'field list'
[SQL: INSERT INTO archives_crusher_comment (time_updated, crusher_id, reason_msg, reason_msg_nullable) VALUES (?, ?, ?, ?) RETURNING archives_crusher_comment.id, archives_crusher_comment.time_created]
[parameters: (None, None, 'msg', None)]
(Background on this error at: https://sqlalche.me/e/20/e3q8)
Traceback (most recent call last):
  File "D:\PESK\Projects\TimeManagementWebApp_prod\venv\lib\site-packages\sqlalchemy\engine\base.py", line 1964, in _exec_single_context
    self.dialect.do_execute(
  File "D:\PESK\Projects\TimeManagementWebApp_prod\venv\lib\site-packages\sqlalchemy\engine\default.py", line 747, in do_execute
    cursor.execute(statement, parameters)
  File "D:\PESK\Projects\TimeManagementWebApp_prod\venv\lib\site-packages\mariadb\cursors.py", line 315, in execute
    self._execute_binary()
mariadb.OperationalError: Unknown column 'time_updated' in 'field list'

The above exception was the direct cause of the following exception:

Traceback (most recent call last):
  File "D:\PESK\Projects\WhyDoYouReject\app\main_bp\__init__.py", line 25, in add_msg
    ArchivesCrusherComment(msg).save()
  File "D:\PESK\Projects\WhyDoYouReject\app\models.py", line 8, in save
    db.session.commit()
  File "D:\PESK\Projects\TimeManagementWebApp_prod\venv\lib\site-packages\sqlalchemy\orm\scoping.py", line 538, in commit
    return self._proxied.commit()
  File "D:\PESK\Projects\TimeManagementWebApp_prod\venv\lib\site-packages\sqlalchemy\orm\session.py", line 1903, in commit
    trans.commit(_to_root=True)
  File "<string>", line 2, in commit
  File "D:\PESK\Projects\TimeManagementWebApp_prod\venv\lib\site-packages\sqlalchemy\orm\state_changes.py", line 137, in _go
    ret_value = fn(self, *arg, **kw)
  File "D:\PESK\Projects\TimeManagementWebApp_prod\venv\lib\site-packages\sqlalchemy\orm\session.py", line 1218, in commit
    self._prepare_impl()
  File "<string>", line 2, in _prepare_impl
  File "D:\PESK\Projects\TimeManagementWebApp_prod\venv\lib\site-packages\sqlalchemy\orm\state_changes.py", line 137, in _go
    ret_value = fn(self, *arg, **kw)
  File "D:\PESK\Projects\TimeManagementWebApp_prod\venv\lib\site-packages\sqlalchemy\orm\session.py", line 1193, in _prepare_impl
    self.session.flush()
  File "D:\PESK\Projects\TimeManagementWebApp_prod\venv\lib\site-packages\sqlalchemy\orm\session.py", line 4153, in flush
    self._flush(objects)
  File "D:\PESK\Projects\TimeManagementWebApp_prod\venv\lib\site-packages\sqlalchemy\orm\session.py", line 4289, in _flush
    with util.safe_reraise():
  File "D:\PESK\Projects\TimeManagementWebApp_prod\venv\lib\site-packages\sqlalchemy\util\langhelpers.py", line 147, in __exit__
    raise exc_value.with_traceback(exc_tb)
  File "D:\PESK\Projects\TimeManagementWebApp_prod\venv\lib\site-packages\sqlalchemy\orm\session.py", line 4250, in _flush
    flush_context.execute()
  File "D:\PESK\Projects\TimeManagementWebApp_prod\venv\lib\site-packages\sqlalchemy\orm\unitofwork.py", line 467, in execute
    rec.execute(self)
  File "D:\PESK\Projects\TimeManagementWebApp_prod\venv\lib\site-packages\sqlalchemy\orm\unitofwork.py", line 644, in execute
    util.preloaded.orm_persistence.save_obj(
  File "D:\PESK\Projects\TimeManagementWebApp_prod\venv\lib\site-packages\sqlalchemy\orm\persistence.py", line 93, in save_obj
    _emit_insert_statements(
  File "D:\PESK\Projects\TimeManagementWebApp_prod\venv\lib\site-packages\sqlalchemy\orm\persistence.py", line 1188, in _emit_insert_statements
    result = connection.execute(
  File "D:\PESK\Projects\TimeManagementWebApp_prod\venv\lib\site-packages\sqlalchemy\engine\base.py", line 1414, in execute
    return meth(
  File "D:\PESK\Projects\TimeManagementWebApp_prod\venv\lib\site-packages\sqlalchemy\sql\elements.py", line 485, in _execute_on_connection
    return connection._execute_clauseelement(
  File "D:\PESK\Projects\TimeManagementWebApp_prod\venv\lib\site-packages\sqlalchemy\engine\base.py", line 1638, in _execute_clauseelement
    ret = self._execute_context(
  File "D:\PESK\Projects\TimeManagementWebApp_prod\venv\lib\site-packages\sqlalchemy\engine\base.py", line 1842, in _execute_context
    return self._exec_single_context(
  File "D:\PESK\Projects\TimeManagementWebApp_prod\venv\lib\site-packages\sqlalchemy\engine\base.py", line 1983, in _exec_single_context
    self._handle_dbapi_exception(
  File "D:\PESK\Projects\TimeManagementWebApp_prod\venv\lib\site-packages\sqlalchemy\engine\base.py", line 2325, in _handle_dbapi_exception
    raise sqlalchemy_exception.with_traceback(exc_info[2]) from e
  File "D:\PESK\Projects\TimeManagementWebApp_prod\venv\lib\site-packages\sqlalchemy\engine\base.py", line 1964, in _exec_single_context
    self.dialect.do_execute(
  File "D:\PESK\Projects\TimeManagementWebApp_prod\venv\lib\site-packages\sqlalchemy\engine\default.py", line 747, in do_execute
    cursor.execute(statement, parameters)
  File "D:\PESK\Projects\TimeManagementWebApp_prod\venv\lib\site-packages\mariadb\cursors.py", line 315, in execute
    self._execute_binary()
sqlalchemy.exc.OperationalError: (mariadb.OperationalError) Unknown column 'time_updated' in 'field list'
[SQL: INSERT INTO archives_crusher_comment (time_updated, crusher_id, reason_msg, reason_msg_nullable) VALUES (?, ?, ?, ?) RETURNING archives_crusher_comment.id, archives_crusher_comment.time_created]
[parameters: (None, None, 'msg', None)]
(Background on this error at: https://sqlalche.me/e/20/e3q8)
2023-03-31 14:22:58,850:app.main_bp:INFO:Msg: msg added in DB.
2023-03-31 14:24:22,702:app.main_bp:INFO:Msg: My msg added in DB.
2023-03-31 14:26:13,455:app.main_bp:ERROR:Add empty msg fails with (mariadb.IntegrityError) Column 'reason_msg' cannot be null
[SQL: INSERT INTO archives_crusher_comment (time_updated, crusher_id, reason_msg, reason_msg_nullable) VALUES (?, ?, ?, ?) RETURNING archives_crusher_comment.id, archives_crusher_comment.time_created]
[parameters: (None, None, None, None)]
(Background on this error at: https://sqlalche.me/e/20/gkpj)
Traceback (most recent call last):
  File "D:\PESK\Projects\TimeManagementWebApp_prod\venv\lib\site-packages\sqlalchemy\engine\base.py", line 1964, in _exec_single_context
    self.dialect.do_execute(
  File "D:\PESK\Projects\TimeManagementWebApp_prod\venv\lib\site-packages\sqlalchemy\engine\default.py", line 747, in do_execute
    cursor.execute(statement, parameters)
  File "D:\PESK\Projects\TimeManagementWebApp_prod\venv\lib\site-packages\mariadb\cursors.py", line 317, in execute
    self._initresult()
mariadb.IntegrityError: Column 'reason_msg' cannot be null

The above exception was the direct cause of the following exception:

Traceback (most recent call last):
  File "D:\PESK\Projects\WhyDoYouReject\app\main_bp\__init__.py", line 33, in add_empty_msg
    ArchivesCrusherComment().save()
  File "D:\PESK\Projects\WhyDoYouReject\app\models.py", line 8, in save
    db.session.commit()
  File "D:\PESK\Projects\TimeManagementWebApp_prod\venv\lib\site-packages\sqlalchemy\orm\scoping.py", line 538, in commit
    return self._proxied.commit()
  File "D:\PESK\Projects\TimeManagementWebApp_prod\venv\lib\site-packages\sqlalchemy\orm\session.py", line 1903, in commit
    trans.commit(_to_root=True)
  File "<string>", line 2, in commit
  File "D:\PESK\Projects\TimeManagementWebApp_prod\venv\lib\site-packages\sqlalchemy\orm\state_changes.py", line 137, in _go
    ret_value = fn(self, *arg, **kw)
  File "D:\PESK\Projects\TimeManagementWebApp_prod\venv\lib\site-packages\sqlalchemy\orm\session.py", line 1218, in commit
    self._prepare_impl()
  File "<string>", line 2, in _prepare_impl
  File "D:\PESK\Projects\TimeManagementWebApp_prod\venv\lib\site-packages\sqlalchemy\orm\state_changes.py", line 137, in _go
    ret_value = fn(self, *arg, **kw)
  File "D:\PESK\Projects\TimeManagementWebApp_prod\venv\lib\site-packages\sqlalchemy\orm\session.py", line 1193, in _prepare_impl
    self.session.flush()
  File "D:\PESK\Projects\TimeManagementWebApp_prod\venv\lib\site-packages\sqlalchemy\orm\session.py", line 4153, in flush
    self._flush(objects)
  File "D:\PESK\Projects\TimeManagementWebApp_prod\venv\lib\site-packages\sqlalchemy\orm\session.py", line 4289, in _flush
    with util.safe_reraise():
  File "D:\PESK\Projects\TimeManagementWebApp_prod\venv\lib\site-packages\sqlalchemy\util\langhelpers.py", line 147, in __exit__
    raise exc_value.with_traceback(exc_tb)
  File "D:\PESK\Projects\TimeManagementWebApp_prod\venv\lib\site-packages\sqlalchemy\orm\session.py", line 4250, in _flush
    flush_context.execute()
  File "D:\PESK\Projects\TimeManagementWebApp_prod\venv\lib\site-packages\sqlalchemy\orm\unitofwork.py", line 467, in execute
    rec.execute(self)
  File "D:\PESK\Projects\TimeManagementWebApp_prod\venv\lib\site-packages\sqlalchemy\orm\unitofwork.py", line 644, in execute
    util.preloaded.orm_persistence.save_obj(
  File "D:\PESK\Projects\TimeManagementWebApp_prod\venv\lib\site-packages\sqlalchemy\orm\persistence.py", line 93, in save_obj
    _emit_insert_statements(
  File "D:\PESK\Projects\TimeManagementWebApp_prod\venv\lib\site-packages\sqlalchemy\orm\persistence.py", line 1188, in _emit_insert_statements
    result = connection.execute(
  File "D:\PESK\Projects\TimeManagementWebApp_prod\venv\lib\site-packages\sqlalchemy\engine\base.py", line 1414, in execute
    return meth(
  File "D:\PESK\Projects\TimeManagementWebApp_prod\venv\lib\site-packages\sqlalchemy\sql\elements.py", line 485, in _execute_on_connection
    return connection._execute_clauseelement(
  File "D:\PESK\Projects\TimeManagementWebApp_prod\venv\lib\site-packages\sqlalchemy\engine\base.py", line 1638, in _execute_clauseelement
    ret = self._execute_context(
  File "D:\PESK\Projects\TimeManagementWebApp_prod\venv\lib\site-packages\sqlalchemy\engine\base.py", line 1842, in _execute_context
    return self._exec_single_context(
  File "D:\PESK\Projects\TimeManagementWebApp_prod\venv\lib\site-packages\sqlalchemy\engine\base.py", line 1983, in _exec_single_context
    self._handle_dbapi_exception(
  File "D:\PESK\Projects\TimeManagementWebApp_prod\venv\lib\site-packages\sqlalchemy\engine\base.py", line 2325, in _handle_dbapi_exception
    raise sqlalchemy_exception.with_traceback(exc_info[2]) from e
  File "D:\PESK\Projects\TimeManagementWebApp_prod\venv\lib\site-packages\sqlalchemy\engine\base.py", line 1964, in _exec_single_context
    self.dialect.do_execute(
  File "D:\PESK\Projects\TimeManagementWebApp_prod\venv\lib\site-packages\sqlalchemy\engine\default.py", line 747, in do_execute
    cursor.execute(statement, parameters)
  File "D:\PESK\Projects\TimeManagementWebApp_prod\venv\lib\site-packages\mariadb\cursors.py", line 317, in execute
    self._initresult()
sqlalchemy.exc.IntegrityError: (mariadb.IntegrityError) Column 'reason_msg' cannot be null
[SQL: INSERT INTO archives_crusher_comment (time_updated, crusher_id, reason_msg, reason_msg_nullable) VALUES (?, ?, ?, ?) RETURNING archives_crusher_comment.id, archives_crusher_comment.time_created]
[parameters: (None, None, None, None)]
(Background on this error at: https://sqlalche.me/e/20/gkpj)
2023-03-31 14:30:26,132:app.main_bp:INFO:Empty msg added in DB.
2023-03-31 14:35:53,309:app.main_bp:INFO:Msg: На фабрике произошла авария. Один из трактов не работал. Необходимо поддерживать переработку. added in DB.
